Workbook

Sheet 總覽
A1: 東北雪國 × 銀山溫泉 規劃表（2027/1/22–1/31）
A2: 票價為 2026/9 公開資料的參考價，非即時報價；在「機票價格」工作表 J、K 欄填入你實際查到的價格，全部表格會自動改用你的價格。
A4: 設定（黃底可修改）
A5: 匯率（1 日圓 = ? 新台幣） | B5: 0.21 | C5: 假設值：約 0.21，出發前請依當時匯率調整
A6: 旅行人數 | B6: 1 | C6: 票價與費用皆為每人；改人數會影響總覽的「全員合計」
A7: 銀山溫泉住宿費（已訂，日圓/人） | B7: 0 | C7: 使用者已訂 1/29；請填入實際金額
A9: 方案總比較（每人，新台幣）
A10: 方案 | B10: 日期 | C10: 請假天數 | D10: 機票＋行李 | E10: 往返銀山的陸路交通 | F10: 機票＋交通合計 | G10: 全員合計 | H10: 推薦
A11: =方案比較!A5&" "&方案比較!B5 -> ★ 早去晚回：長榮去＋虎航回（定案） | B11: =方案比較!C5 -> 1/26 二–1/31 日 | C11: =方案比較!D5 -> 4 | D11: =方案比較!G5+方案比較!H5 -> 15538 | E11: =方案比較!J5+3050*$B$5 -> 640.5 | F11: =D11+E11 -> 16178.5 | G11: =F11*$B$6 -> 16178.5 | H11: ★ 定案（早去晚回）
A12: =方案比較!A6&" "&方案比較!B6 -> A 虎航來回（最便宜） | B12: =方案比較!C6 -> 1/26 二–1/31 日 | C12: =方案比較!D6 -> 4 | D12: =方案比較!G6+方案比較!H6 -> 11576 | E12: =方案比較!J6+3050*$B$5 -> 640.5 | F12: =D12+E12 -> 12216.5 | G12: =F12*$B$6 -> 12216.5 | H12: 最便宜
A13: =方案比較!A7&" "&方案比較!B7 -> B 長榮去＋虎航回 | B13: =方案比較!C7 -> 1/27 三–1/31 日 | C13: =方案比較!D7 -> 3 | D13: =方案比較!G7+方案比較!H7 -> 15538 | E13: =方案比較!J7+3050*$B$5 -> 640.5 | F13: =D13+E13 -> 16178.5 | G13: =F13*$B$6 -> 16178.5 | H13: 最短請假
A14: =方案比較!A8&" "&方案比較!B8 -> C 星宇來回 | B14: =方案比較!C8 -> 1/27 三–1/31 日 | C14: =方案比較!D8 -> 3 | D14: =方案比較!G8+方案比較!H8 -> 19586 | E14: =方案比較!J8+3050*$B$5 -> 640.5 | F14: =D14+E14 -> 20226.5 | G14: =F14*$B$6 -> 20226.5 | H14: 最短請假
A15: =方案比較!A9&" "&方案比較!B9 -> D 松山⇄羽田來回（長榮） | B15: =方案比較!C9 -> 1/26 二–1/31 日 | C15: =方案比較!D9 -> 4 | D15: =方案比較!G9+方案比較!H9 -> 16526 | E15: =方案比較!J9+3050*$B$5 -> 5493.6 | F15: =D15+E15 -> 22019.6 | G15: =F15*$B$6 -> 22019.6
A16: =方案比較!A10&" "&方案比較!B10 -> E 開口：虎航去仙台＋羽田回松山 | B16: =方案比較!C10 -> 1/26 二–1/31 日 | C16: =方案比較!D10 -> 4 | D16: =方案比較!G10+方案比較!H10 -> 16054 | E16: =方案比較!J10+3050*$B$5 -> 2889.6 | F16: =D16+E16 -> 18943.6 | G16: =F16*$B$6 -> 18943.6
A17: =方案比較!A11&" "&方案比較!B11 -> F 樂桃 桃園⇄羽田＋新幹線 | B17: =方案比較!C11 -> 1/26 二–1/31 日 | C17: =方案比較!D11 -> 4 | D17: =方案比較!G11+方案比較!H11 -> 12772 | E17: =方案比較!J11+3050*$B$5 -> 5493.6 | F17: =D17+E17 -> 18265.6 | G17: =F17*$B$6 -> 18265.6
A18: 「往返銀山的陸路交通」＝仙台⇄大石田 JR 與機場線（¥3,050）＋各方案額外的新幹線費用。
A20: 定案行程 全程預算（每人，新台幣）
A21: 機票＋行李 | B21: =D11 -> 15538
A22: 當地交通、住宿、門票、餐費（含銀山溫泉） | B22: =行程預算!I14 -> 19763.1 | C22: 當地交通已含仙台⇄大石田等車資，所以不另加上方表格的陸路交通
A23: 合計 | B23: =B21+B22 -> 35301.1
A24: 全員合計 | B24: =B23*B6 -> 35301.1
A26: 圖例：藍字＝輸入或估計值 黑字＝公式 綠字＝引用其他工作表 黃底＝請你填寫或修改

Sheet 即時查價 10-9
A1: Google Flights 即時查價（2026/10/9 查詢；回程含 1/30–2/3，每人單程經濟艙，含稅，新台幣）
A2: 有列出價格＝當下還有位子可以買。價格會變動，而且廉航不含托運行李。「商務艙」代表經濟艙已經查不到，只剩商務艙。
A4: 日期 | B4: 航線 | C4: 航空 | D4: 起飛 → 抵達 | E4: 價格 | F4: 艙等 | G4: 狀態／備註
A5: 1/26 二 | B5: 桃園→仙台 | C5: 長榮航空 | D5: 10:15 → 14:25 | E5: 25165 | F5: 經濟 | G5: 有位；比原本查到的 08:45 晚
A6: 1/26 二 | B6: 桃園→仙台 | C6: 星宇航空 | D6: 11:50 → 16:00 | E6: 22778 | F6: 經濟 | G6: 有位
A7: 1/26 二 | B7: 桃園→仙台 | C7: 台灣虎航 | D7: 14:35 → 18:45 | E7: 15599 | F7: 經濟 | G7: 有位；不含托運行李
A8: 1/27 三 | B8: 桃園→仙台 | C8: 星宇航空 | D8: 11:50 → 16:00 | E8: 15727 | F8: 經濟 | G8: 有位，比 1/26 便宜很多
A9: 1/27 三 | B9: 桃園→仙台 | C9: 長榮航空 | D9: 10:15 → 14:25 | E9: 17775 | F9: 經濟 | G9: 有位
A10: 1/28 四 | B10: 桃園→仙台 | C10: 台灣虎航 | D10: 14:35 → 18:45 | E10: 14099 | F10: 經濟 | G10: 有位
A11: 1/28 四 | B11: 桃園→仙台 | C11: 星宇航空 | D11: 11:50 → 16:00 | E11: 22778 | F11: 經濟 | G11: 有位
A12: 1/26 二 | B12: 松山→羽田 | C12: 日航／華航 | D12: 09:10 → 13:00 | E12: 14137 | F12: 經濟 | G12: 有位，早班又便宜
A13: 1/26 二 | B13: 松山→羽田 | C13: 長榮航空 | D13: 07:15 → 11:00 | E13: 17309 | F13: 經濟 | G13: 有位，最早的一班
A14: 1/26 二 | B14: 松山→羽田 | C14: 華航／日航 | D14: 09:00 → 12:50 | E14: 17246 | F14: 經濟 | G14: 有位
A15: 1/31 日 | B15: 仙台→桃園 | C15: 長榮航空 | D15: 16:15 → 19:30 | E15: 33008 | F15: 商務 | G15: 經濟艙查不到，只剩商務艙
A16: 1/31 日 | B16: 仙台→桃園 | C16: 星宇航空 | D16: 17:25 → 20:35 | E16: 34279 | F16: 商務 | G16: 經濟艙查不到，只剩商務艙
A17: 1/31 日 | B17: 仙台→桃園 | C17: 台灣虎航 | D17: — | F17: — | G17: 沒有班次（或已售完）
A18: 1/30 六 | B18: 仙台→桃園 | C18: 直飛 | D18: — | F18: — | G18: 沒有直飛，只有轉機（約 NT$12,900 起，飛行 19 小時以上）
A19: 2/1 一 | B19: 仙台→桃園 | C19: 星宇航空 | D19: 17:25 → 20:35 | E19: 34247 | F19: 商務 | G19: 唯一的直飛，經濟艙查不到
A20: 2/2 二 | B20: 仙台→桃園 | C20: 台灣虎航 | D20: 19:40 → 23:00 | E20: 16439 | F20: 經濟 | G20: 有位；不含托運行李
A21: 2/2 二 | B21: 仙台→桃園 | C21: 長榮航空 | D21: 16:15 → 19:30 | E21: 20518 | F21: 經濟 | G21: 有位；含行李
A22: 2/3 三 | B22: 仙台→桃園 | C22: 直飛 | D22: — | F22: — | G22: 沒有直飛
A23: 1/27 三 | B23: 松山→羽田 | C23: 長榮航空 | D23: 07:15 → 11:00 | E23: 17309 | F23: 經濟 | G23: 有位
A24: 1/27 三 | B24: 松山→羽田 | C24: 華航／日航 | D24: 09:00 → 12:50 | E24: 17246 | F24: 經濟 | G24: 有位
A25: 2/1 一 | B25: 成田→桃園 | C25: 泰國獅航 | D25: 18:15 → 21:10 | E25: 10294 | F25: 經濟 | G25: 有位；2/1 最便宜的晚班
A26: 2/1 一 | B26: 成田→桃園 | C26: 酷航 | D26: 19:45 → 22:55 | E26: 10752 | F26: 經濟 | G26: 有位
A27: 2/1 一 | B27: 成田→桃園 | C27: 台灣虎航 | D27: 18:25 → 21:50 | E27: 13137 | F27: 經濟 | G27: 有位
A28: 2/1 一 | B28: 成田→桃園 | C28: 星宇航空 | D28: 20:10 → 23:20 | E28: 16591 | F28: 經濟 | G28: 有位；含行李
A29: 2/1 一 | B29: 成田→桃園 | C29: 星宇航空 | D29: 13:45 → 16:50 | E29: 16591 | F29: 經濟 | G29: 有位；含行李
A30: 2/1 一 | B30: 羽田→松山 | C30: 長榮航空 | D30: 12:15 → 15:05 | E30: 14855 | F30: 經濟 | G30: 有位；回松山最晚的平價班次
A31: 2/2 二 | B31: 成田→桃園 | C31: 泰國獅航 | D31: 17:25 → 20:20 | E31: 16343 | F31: 經濟 | G31: 有位
A32: 2/2 二 | B32: 成田→桃園 | C32: 酷航 | D32: 19:45 → 23:00 | E32: 10752 | F32: 經濟 | G32: 有位
A33: 1/30 六 | B33: 成田→桃園 | C33: 酷航 | D33: 19:45 → 22:55 | E33: 10752 | F33: 經濟 | G33: 有位
A34: 1/31 日 | B34: 成田→桃園 | C34: 泰國獅航 | D34: 17:25 → 20:20 | E34: 14542 | F34: 經濟 | G34: 有位；晚回又能搭捷運回家
... A41: 1/31 日 | B41: 羽田→松山 | C41: 日航／華航 | D41: 18:05 → 21:00 | E41: 37120 | F41: 經濟 | G41: 有位，但很貴

Sheet 新方案 10-10
A1: 不經仙台／不從仙台回的方案（Google Flights 2026/10/10 查到可購買的經濟艙，每人單程含稅，新台幣）
A2: 價格隨時會變；廉航（酷航、虎航、泰國獅航、捷星、樂桃）不含托運行李。日圓換算引用「總覽」B5 的匯率。
A4: 方案 | B4: 請假 | C4: 去程 | D4: 去程票價 | E4: 回程 | F4: 回程票價 | G4: 行李加購（估） | H4: 陸路交通（日圓） | I4: 合計（新台幣） | J4: 評語
A5: ① 東京進出（推薦・最便宜） | B5: 4 | C5: 1/27 三 酷航 06:50 桃園→成田 10:55 | D5: 9725 | E5: 2/1 一 泰國獅航 18:15 成田→桃園 21:10 | F5: 10309 | G5: 2000 | H5: =2600+11670+12780+2600 -> 29650 | I5: =D5+F5+G5+H5*總覽!$B$5 -> 28260.5 | J5: 早去晚回又最便宜；21:10 落地可搭捷運回家。備選去程：虎航 06:10（10,699）；備選回程：酷航 19:45（10,770）
A6: ② 東京進出（同樣日期，含行李的航空） | B6: 4 | C6: 1/27 三 星宇 08:25 桃園→成田 12:35 | D6: 19040 | E6: 2/1 一 星宇 20:10 成田→桃園 23:20 | F6: 16616 | G6: 0 | H6: =2600+11670+12780+2600 -> 29650 | I6: =D6+F6+G6+H6*總覽!$B$5 -> 41882.5 | J6: 不用另買行李、座位比較舒適；回程落地較晚
A7: ③ 仙台進、東京出 | B7: 4 | C7: 1/27 三 星宇 11:50 桃園→仙台 16:00 | D7: 15727 | E7: 2/1 一 泰國獅航 18:15 成田→桃園 21:10 | F7: 10309 | G7: 1000 | H7: =680+1690+12780+2600 -> 17750 | I7: =D7+F7+G7+H7*總覽!$B$5 -> 30763.5 | J7: 第一天可以逛仙台；去程含行李。1/30 從大石田直達東京
A8: ④ 松山進出（離家最近） | B8: 4 | C8: 1/27 三 長榮 07:15 松山→羽田 11:00 | D8: 17315 | E8: 2/1 一 長榮 12:15 羽田→松山 15:05 | F8: 14855 | G8: 0 | H8: =600+11670+12780+600 -> 25650 | I8: =D8+F8+G8+H8*總覽!$B$5 -> 37556.5 | J8: 交通最方便，但回程是中午，不算晚回
A9: ⑤ 秋田進、新潟出（東北其他機場） | B9: 4 | C9: 1/28 四 虎航 08:30 桃園→秋田 12:40 | D9: 13099 | E9: 2/1 一 虎航 19:00 新潟→桃園 22:30 | F9: 10891 | G9: 2000 | H9: =6000+6000 -> 12000 | I9: =D9+F9+G9+H9*總覽!$B$5 -> 28510 | J9: 秋田只有 1/28 有飛、到銀山要 4.5–5 小時；只能玩 1/28 到 2/1，不推薦
A11: 陸路交通：新幹線 東京→山形 ¥11,670、大石田→東京 ¥12,780（2026/3 調價後指定席）；成田⇄東京 Skyliner／N'EX 約 ¥2,600；松山方案用羽田京急／單軌約 ¥600。JR EAST PASS 5 日券 ¥35,000 不划算。
A12: 東北其他機場：福島、山形、庄內沒有台北直飛；花卷（虎航 1/27、1/30）、青森（長榮）有直飛，但到銀山溫泉都要 4.5 小時以上。
A14: 方案 ① 東京進出：每日行程（1/27 三 – 2/1 一，6 天 5 夜）
A15: 日期 | B15: 時間 | C15: 行程 | D15: 交通 | E15: 住宿／備註
A16: 1/27 三 | B16: 04:10 | C16: 從淡水搭計程車或前一晚住機場附近 | D16: 首班捷運趕不上 06:50 的班機 | E16: 酷航 TR 06:50 起飛，04:50 前要到機場
B17: 10:55 | C17: 抵達成田 → 東京站 | D17: 成田特快 N'EX 約 1 小時，約 ¥3,100
B18: 13:00 | C18: 東京 → 山形 | D18: 山形新幹線翼號約 2.5–3 小時，¥11,670
B19: 16:00 | C19: 山形站 → 藏王溫泉 | D19: 山交巴士約 40 分鐘，¥1,200 | E19: 住藏王溫泉；有點燈的日子 17:00–21:00 可以看樹冰夜景
A20: 1/28 四 | B20: 08:30 | C20: 藏王纜車上山看樹冰 | D20: 纜車來回約 ¥4,400 | E20: 早上風比較小
B21: 13:00 | C21: 藏王 → 山形 → 山寺 | D21: 巴士＋JR 仙山線約 20 分鐘 | E21: 爬 1,015 階雪中石梯，要防滑鞋
B22: 17:30 | C22: 回山形，晚餐吃米澤牛 | E22: 住山形站附近
A23: 1/29 五 | B23: 11:00 | C23: 山形 → 大石田 | D23: JR 奧羽本線或新幹線
B24: 13:40 | C24: 大石田 → 銀山溫泉 | D24: 旅館接送或はながさ巴士（只收現金） | E24: ♨ 住銀山溫泉（已訂）；16:45 藍調時刻拍瓦斯燈
A25: 1/30 六 | B25: 06:30 | C25: 清晨溫泉街拍照 | E25: 人最少的時段
B26: 11:00 | C26: 銀山溫泉 → 大石田 → 東京 | D26: 新幹線翼號約 3 小時，¥12,780 | E26: 大件行李可以從旅館用宅急便寄到東京飯店（約 ¥2,000–3,700）
B27: 15:30 | C27: 抵達東京 | E27: 住上野／日暮里一帶，回程搭 Skyliner 最方便
A28: 1/31 日 | B28: 全天 | C28: 東京自由行 | E28: 淺草、晴空塔、上野、銀座等
A29: 2/1 一 | B29: 上午 | C29: 東京半天、買伴手禮
B30: 15:30 | C30: 上野／日暮里 → 成田 | D30: Skyliner 約 45 分鐘，約 ¥2,500 | E30: 最晚 16:15 到機場報到
B31: 18:15 | C31: 泰國獅航 SL 成田 → 桃園 21:10 | E31: 托運行李要在訂票時一起買
A33: 方案 ③ 仙台進、東京出：1/27 星宇 11:50 → 16:00 到仙台，住仙台；1/28 仙台 → 山寺 → 藏王；1/29 早上看樹冰 → 銀山溫泉；1/30 起和方案 ① 一樣。

Sheet 仙台進出 10-10
A1: 仙台進出：目前還買得到的直飛（Google Flights 2026/10/10，每人單程含稅，新台幣）
A2: 去程查 1/22–1/28、回程查 1/30–2/3。紅底＝只剩商務艙或已售完；沒列出的日期＝當天沒有直飛。航空公司不公開剩餘座位數；星宇官網 1/28–2/3 仙台回程經濟艙全部售完。虎航不含托運行李（20kg 訂票時加購 NT$950）。
A4: 日期 | B4: 方向 | C4: 航空 | D4: 起飛 → 抵達 | E4: 價格 | F4: 艙等 | G4: 備註
A5: 1/22 五 | B5: 桃園→仙台 | C5: 長榮航空 | D5: 10:15 → 14:25 | E5: 44798 | F5: 商務 | G5: 經濟艙售完
A6: 1/23 六 | B6: 桃園→仙台 | C6: 星宇航空 | D6: 11:50 → 16:00 | E6: 44374 | F6: 商務 | G6: 經濟艙售完
A7: 1/24 日 | B7: 桃園→仙台 | C7: 台灣虎航 | D7: 14:35 → 18:45 | E7: 15599 | F7: 經濟
A8: 1/24 日 | B8: 桃園→仙台 | C8: 長榮航空 | D8: 10:15 → 14:25 | E8: 27591 | F8: 經濟
A9: 1/25 一 | B9: 桃園→仙台 | C9: — | D9: — | F9: — | G9: 沒有直飛
A10: 1/26 二 | B10: 桃園→仙台 | C10: 台灣虎航 | D10: 14:35 → 18:45 | E10: 15599 | F10: 經濟
A11: 1/26 二 | B11: 桃園→仙台 | C11: 星宇航空 | D11: 11:50 → 16:00 | E11: 22784 | F11: 經濟 | G11: 星宇官網：只剩「全額」票價，便宜票價已售完，快滿了
A12: 1/26 二 | B12: 桃園→仙台 | C12: 長榮航空 | D12: 10:15 → 14:25 | E12: 25171 | F12: 經濟 | G12: 含行李
A13: 1/27 三 | B13: 桃園→仙台 | C13: 星宇航空 | D13: 11:50 → 16:00 | E13: 15733 | F13: 經濟 | G13: 星宇官網：超值 15,733／基本 17,480／全額 22,784 三種票價都還有，座位最充足
A14: 1/27 三 | B14: 桃園→仙台 | C14: 長榮航空 | D14: 10:15 → 14:25 | E14: 17781 | F14: 經濟 | G14: 含行李；最早抵達
A15: 1/28 四 | B15: 桃園→仙台 | C15: 台灣虎航 | D15: 14:35 → 18:45 | E15: 14099 | F15: 經濟 | G15: 去程最便宜
A16: 1/28 四 | B16: 桃園→仙台 | C16: 星宇航空 | D16: 11:50 → 16:00 | E16: 22784 | F16: 經濟 | G16: 星宇官網：只剩「全額」票價，快滿了
A17: 1/28 四 | B17: 桃園→仙台 | C17: 長榮航空 | D17: 10:15 → 14:25 | E17: 44798 | F17: 商務 | G17: 經濟艙售完
A18: 1/30 六 | B18: 仙台→桃園 | C18: — | D18: — | F18: — | G18: 沒有直飛
A19: 1/31 日 | B19: 仙台→桃園 | C19: 長榮航空 | D19: 16:15 → 19:30 | E19: 33029 | F19: 商務 | G19: 經濟艙售完
A20: 1/31 日 | B20: 仙台→桃園 | C20: 星宇航空 | D20: 17:25 → 20:35 | F20: 售完 | G20: 星宇官網：整班已售完（含商務艙）
A21: 2/1 一 | B21: 仙台→桃園 | C21: 星宇航空 | D21: 17:25 → 20:35 | E21: 34301 | F21: 商務 | G21: 星宇官網：經濟艙已售完
A22: 2/2 二 | B22: 仙台→桃園 | C22: 台灣虎航 | D22: 19:40 → 23:00 | E22: 16466 | F22: 經濟 | G22: 回程唯一的平價選擇；落地晚
A23: 2/2 二 | B23: 仙台→桃園 | C23: 長榮航空 | D23: 16:15 → 19:30 | E23: 20549 | F23: 經濟 | G23: 含行李
A24: 2/3 三 | B24: 仙台→桃園 | C24: — | D24: — | F24: — | G24: 沒有直飛
A26: 可行的組合（經濟艙去回）
A27: 組合 | B27: 請假 | C27: 去程 | D27: 去程價 | E27: 回程 | F27: 回程價 | G27: 行李加購 | H27: 機票合計 | I27: 說明
A28: Ⓐ 虎航去＋虎航回（最便宜） | B28: 4 | C28: 1/28 四 虎航 14:35 | D28: 14099 | E28: 2/2 二 虎航 19:40 | F28: 16466 | G28: 1900 | H28: =D28+F28+G28 -> 32465 | I28: 最便宜；但去程下午、回程 23:00 落地
A29: Ⓑ 虎航去＋長榮回（推薦） | B29: 4 | C29: 1/28 四 虎航 14:35 | D29: 14099 | E29: 2/2 二 長榮 16:15 | F29: 20549 | G29: 950 | H29: =D29+F29+G29 -> 35598 | I29: 請假 4 天；19:30 落地，可以搭捷運回家
A30: Ⓒ 星宇去＋長榮回 | B30: 4 | C30: 1/28 四 星宇 11:50 | D30: 22784 | E30: 2/2 二 長榮 16:15 | F30: 20549 | G30: 0 | H30: =D30+F30+G30 -> 43333 | I30: 兩段都含行李，去程比較早
A31: Ⓓ 星宇去＋虎航回（早去） | B31: 5 | C31: 1/27 三 星宇 11:50 | D31: 15733 | E31: 2/2 二 虎航 19:40 | F31: 16466 | G31: 950 | H31: =D31+F31+G31 -> 33149 | I31: 多請 1 天，換到便宜的早一點出發
A32: Ⓔ 長榮去＋長榮回（早去） | B32: 5 | C32: 1/27 三 長榮 10:15 | D32: 17781 | E32: 2/2 二 長榮 16:15 | F32: 20549 | G32: 0 | H32: =D32+F32+G32 -> 38330 | I32: 最早抵達、全程含行李，7 天 6 夜
A33: Ⓕ 星宇去＋1/31 商務艙回 | B33: 4 | C33: 1/27 三 星宇 11:50 | D33: 15733 | E33: 1/31 日 長榮商務 16:15 | F33: 33029 | G33: 0 | H33: =D33+F33+G33 -> 48762 | I33: 維持原本日期，但回程只剩商務艙
A35: Ⓑ 行程：1/28 四 – 2/2 二（6 天 5 夜，請假 1/28、1/29、2/1、2/2）
A36: 日期 | B36: 行程 | G36: 住宿
A37: 1/28 四 | B37: 虎航 14:35 桃園 → 18:45 仙台 → 仙台機場線到仙台站，晚餐吃牛舌 | G37: 仙台
A38: 1/29 五 | B38: 早上 JR 仙山線到山寺，爬雪中石階 → 山形 → 大石田 → 下午進銀山溫泉，16:45 拍瓦斯燈藍調時刻 | G38: ♨ 銀山溫泉（已訂）
A39: 1/30 六 | B39: 清晨溫泉街拍照 → 大石田 → 山形 → 巴士到藏王溫泉，有點燈的話看樹冰夜景 | G39: 藏王溫泉
A40: 1/31 日 | B40: 早上搭纜車看樹冰 → 巴士到仙台（約 1.5 小時）或在山形市區逛 | G40: 仙台（或秋保、作並溫泉）
A41: 2/1 一 | B41: 松島遊覽船、瑞巖寺、烤牡蠣 → 下午回仙台逛一番町 | G41: 仙台
A42: 2/2 二 | B42: 仙台市區（仙台城跡、瑞鳳殿）→ 14:30 前往機場 → 長榮 16:15 起飛，19:30 抵達桃園 | G42: —

Sheet 非仙台回程 10-10
A1: 仙台進、其他東北機場回（Google Flights 2026/10/10，每人單程經濟艙含稅，新台幣）
A2: 去程皆以 1/27（三）星宇 11:50 桃園→仙台（NT$15,733，含行李，目前位子最多）計算；也可以改搭長榮 10:15（NT$17,781）。福島、山形機場 1/30–2/1 沒有直飛。陸路交通為估計值。
A4: 方案 | B4: 回程航班 | C4: 回程票價 | D4: 行李加購 | E4: 去程票價 | F4: 陸路交通（日圓，估） | G4: 合計（新台幣） | H4: 請假 | I4: 旅遊天數 | J4: 評語
A5: Ⓐ 秋田回（1/31 日） | B5: 虎航 14:10 秋田→桃園 17:25 | C5: 11147 | D5: 950 | E5: 15733 | F5: 12000 | G5: =C5+D5+E5+F5*總覽!$B$5 -> 30350 | H5: 3 | I5: 5 天 4 夜 | J5: 只請 3 天最省假；1/30 從銀山溫泉到乳頭溫泉住一晚，1/31 搭秋田新幹線到秋田再去機場。落地 17:25，不算晚回
A6: Ⓑ 青森回（2/1 一）★ | B6: 長榮 15:30 青森→桃園 19:00 | C6: 11999 | D6: 0 | E6: 15733 | F6: 22000 | G6: =C6+D6+E6+F6*總覽!$B$5 -> 32352 | H6: 4 | I6: 6 天 5 夜 | J6: 全程都是全服務航空、含行李；回程票價最便宜；多玩乳頭溫泉＋青森（酸湯溫泉／八甲田）；19:00 落地
A7: Ⓒ 花卷回（1/30 六） | B7: 虎航 17:50 花卷→桃園 21:10 | C7: 11995 | D7: 950 | E7: 15733 | F7: 6500 | G7: =C7+D7+E7+F7*總覽!$B$5 -> 30043 | H7: 3 | I7: 4 天 3 夜 | J7: 行程最短；1/30 要 9:00 前離開銀山溫泉，車程約 4 小時，班次少有風險
A8: Ⓓ 新潟回（2/1 一） | B8: 虎航 19:00 新潟→桃園 22:30 | C8: 10890 | D8: 950 | E8: 15733 | F8: 9000 | G8: =C8+D8+E8+F8*總覽!$B$5 -> 29463 | H8: 4 | I8: 6 天 5 夜 | J8: 機票最便宜，但 22:30 才落地，羽越線冬天常因大雪誤點
A9: Ⓔ 青森回（1/31 日） | B9: 長榮 15:30 青森→桃園 19:00 | C9: 14987 | D9: 0 | E9: 15733 | F9: 16000 | G9: =C9+D9+E9+F9*總覽!$B$5 -> 34080 | H9: 3 | I9: 5 天 4 夜 | J9: 請 3 天也能晚一點回來，但 1/30–1/31 要長途移動
A10: 參考：仙台回（2/2 二） | B10: 長榮 16:15 仙台→桃園 19:30 | C10: 20549 | D10: 0 | E10: 15733 | F10: 3000 | G10: =C10+D10+E10+F10*總覽!$B$5 -> 36912 | H10: 5 | I10: 7 天 6 夜 | J10: 仙台回程經濟艙最早只有 2/2
A12: Ⓑ 青森回 行程：1/27 三 – 2/1 一（請假 1/27、1/28、1/29、2/1）
A13: 日期 | B13: 行程 | I13: 住宿
A14: 1/27 三 | B14: 星宇 11:50 桃園 → 16:00 仙台 → 巴士或 JR 到山形 → 巴士到藏王溫泉（約 2.5 小時） | I14: 藏王溫泉
A15: 1/28 四 | B15: 早上搭纜車看樹冰 → 下午山寺 → 山形 | I15: 山形
A16: 1/29 五 | B16: 山形 → 大石田 → 銀山溫泉，16:45 拍瓦斯燈藍調時刻 | I16: ♨ 銀山溫泉（已訂）
A17: 1/30 六 | B17: 清晨拍照 → 大石田 → 新庄 → 奧羽本線 → 大曲 → 秋田新幹線到田澤湖 → 巴士到乳頭溫泉（約 6 小時，中午前出發） | I17: 乳頭溫泉鄉（鶴之湯等）
A18: 1/31 日 | B18: 乳頭溫泉 → 田澤湖 → 秋田新幹線到盛岡 → 隼號到新青森（約 3.5 小時）→ 青森市區（睡魔之家、A-FACTORY、海鮮） | I18: 青森市（或酸湯溫泉）
A19: 2/1 一 | B19: 上午青森魚菜中心吃自選海鮮丼 → 13:30 搭巴士到機場（約 35 分鐘）→ 長榮 15:30 起飛，19:00 抵達桃園 | I19: —
A21: Ⓐ 秋田回：1/27–1/29 同上；1/30 銀山溫泉 → 乳頭溫泉；1/31 乳頭 → 田澤湖 → 秋田新幹線到秋田（約 1 小時）→ 巴士到機場（約 40 分鐘）→ 虎航 14:10 起飛。
A22: 陸路參考：新庄—大曲之間的奧羽本線班次很少（院內站每天約 7 班），出發前務必查 JR 東日本時刻表；八甲田纜車冬季 9:00–15:40，常因強風停駛。

Sheet 即時查價 10-13
A1: 目前還能買的直飛（Google Flights＋星宇官網，2026/10/13 查詢；每人單程含稅，新台幣）
A2: 不含東京。去程查 1/22–1/28、回程查 1/30–2/2。紅底＝只剩商務艙。沒列出的日期＝當天沒有直飛或已售完。航空公司不公開剩餘座位數。
A4: 日期 | B4: 航線 | C4: 航空 | D4: 起飛 → 抵達（當地） | E4: 價格 | F4: 艙等 | G4: 備註
A5: 1/22 五 | B5: 桃園→仙台 | C5: 長榮航空 | D5: 10:15 → 14:25 | E5: 44798 | F5: 商務 | G5: 經濟艙已售完
A6: 1/23 六 | B6: 桃園→仙台 | C6: 星宇航空 | D6: 11:50 → 16:00 | E6: 22784 | F6: 經濟
A7: 1/24 日 | B7: 桃園→仙台 | C7: 長榮航空 | D7: 10:15 → 14:25 | E7: 27591 | F7: 經濟
A8: 1/24 日 | B8: 桃園→仙台 | C8: 星宇航空 | D8: 11:50 → 16:00 | E8: 44374 | F8: 商務 | G8: 經濟艙已售完
A9: 1/24 日 | B9: 桃園→仙台 | C9: 台灣虎航 | D9: 14:35 → 18:45 | E9: 15599 | F9: 經濟 | G9: 不含托運行李
A10: 1/26 二 | B10: 桃園→仙台 | C10: 長榮航空 | D10: 10:15 → 14:25 | E10: 25171 | F10: 經濟
A11: 1/26 二 | B11: 桃園→仙台 | C11: 星宇航空 | D11: 11:50 → 16:00 | E11: 22784 | F11: 經濟
A12: 1/26 二 | B12: 桃園→仙台 | C12: 台灣虎航 | D12: 14:35 → 18:45 | E12: 15599 | F12: 經濟 | G12: 不含托運行李
A13: 1/27 三 | B13: 桃園→仙台 | C13: 長榮航空 | D13: 10:15 → 14:25 | E13: 20266 | F13: 經濟
A14: 1/27 三 | B14: 桃園→仙台 | C14: 星宇航空 | D14: 11:50 → 16:00 | E14: 17480 | F14: 經濟 | G14: 星宇官網：最便宜的「超值」票已售完，剩基本 17,480／全額 22,784
A15: 1/28 四 | B15: 桃園→仙台 | C15: 長榮航空 | D15: 10:15 → 14:25 | E15: 44798 | F15: 商務 | G15: 經濟艙已售完
A16: 1/28 四 | B16: 桃園→仙台 | C16: 星宇航空 | D16: 11:50 → 16:00 | E16: 22784 | F16: 經濟
A17: 1/28 四 | B17: 桃園→仙台 | C17: 台灣虎航 | D17: 14:35 → 18:45 | E17: 14099 | F17: 經濟 | G17: 不含托運行李
A18: 1/25 一 | B18: 桃園→新潟 | C18: 台灣虎航 | D18: 13:55 → 18:00 | E18: 12799 | F18: 經濟 | G18: 不含托運行李
A19: 1/24 日 | B19: 桃園→秋田 | C19: 台灣虎航 | D19: 08:30 → 12:40 | E19: 14599 | F19: 經濟 | G19: 不含托運行李
A20: 1/28 四 | B20: 桃園→秋田 | C20: 台灣虎航 | D20: 08:30 → 12:40 | E20: 13099 | F20: 經濟 | G20: 不含托運行李
A21: 1/27 三 | B21: 桃園→花卷 | C21: 台灣虎航 | D21: 12:15 → 16:35 | E21: 17099 | F21: 經濟 | G21: 不含托運行李
A22: 1/24 日 | B22: 桃園→青森 | C22: 長榮航空 | D22: 09:55 → 14:20 | E22: 25171 | F22: 經濟
A23: 1/25 一 | B23: 桃園→青森 | C23: 長榮航空 | D23: 09:55 → 14:20 | E23: 25171 | F23: 經濟
A24: 1/26 二 | B24: 桃園→青森 | C24: 長榮航空 | D24: 09:55 → 14:20 | E24: 25171 | F24: 經濟
A25: 1/27 三 | B25: 桃園→青森 | C25: 長榮航空 | D25: 09:55 → 14:20 | E25: 20266 | F25: 經濟
A26: 1/28 四 | B26: 桃園→青森 | C26: 長榮航空 | D26: 09:55 → 14:20 | E26: 25171 | F26: 經濟
A27: 1/31 日 | B27: 仙台→桃園 | C27: 長榮航空 | D27: 16:15 → 19:30 | E27: 33270 | F27: 商務 | G27: 經濟艙已售完
A28: 1/31 日 | B28: 仙台→桃園 | C28: 星宇航空 | D28: 17:25 → 20:35 | E28: 34552 | F28: 商務 | G28: 經濟艙已售完
A29: 2/1 一 | B29: 仙台→桃園 | C29: 星宇航空 | D29: 17:25 → 20:35 | E29: 34552 | F29: 商務 | G29: 經濟艙已售完
A30: 2/2 二 | B30: 仙台→桃園 | C30: 長榮航空 | D30: 16:15 → 19:30 | E30: 33270 | F30: 商務 | G30: 經濟艙已售完
A31: 2/2 二 | B31: 仙台→桃園 | C31: 星宇航空 | D31: 17:25 → 20:35 | E31: 16144 | F31: 經濟 | G31: 星宇官網確認有經濟艙（¥79,370）
A32: 2/2 二 | B32: 仙台→桃園 | C32: 台灣虎航 | D32: 19:40 → 23:00 | E32: 16585 | F32: 經濟 | G32: 不含托運行李
A33: 2/1 一 | B33: 新潟→桃園 | C33: 台灣虎航 | D33: 19:00 → 22:30 | E33: 10970 | F33: 經濟 | G33: 不含托運行李
A34: 1/31 日 | B34: 秋田→桃園 | C34: 台灣虎航 | D34: 14:10 → 17:25 | E34: 11228 | F34: 經濟 | G34: 不含托運行李
A35: 1/30 六 | B35: 花卷→桃園 | C35: 台灣虎航 | D35: 17:50 → 21:10 | E35: 12082 | F35: 經濟 | G35: 不含托運行李
A36: 1/30 六 | B36: 青森→桃園 | C36: 長榮航空 | D36: 15:30 → 19:00 | E36: 20631 | F36: 經濟
A37: 1/31 日 | B37: 青森→桃園 | C37: 長榮航空 | D37: 15:30 → 19:00 | E37: 15099 | F37: 經濟
A38: 2/1 一 | B38: 青森→桃園 | C38: 長榮航空 | D38: 15:30 → 19:00 | E38: 15099 | F38: 經濟
A39: 2/2 二 | B39: 青森→桃園 | C39: 長榮航空 | D39: 15:30 → 19:00 | E39: 15099 | F39: 經濟

Sheet 兩人票價 10-13
A1: 兩人同行：目前還買得到 2 張的機票（Google Flights 以「2 位成人」查詢，2026/10/13；價格＝兩人合計，新台幣）
A2: 能以 2 人報價代表查詢當下至少還有 2 個座位；實際以訂票時為準。陸路＝到山形（藏王）方向的兩人交通費，日圓×匯率（總覽 B5）。廉航行李以每人 NT$1,000 估。
A4: 去程 1/27（三） | B4: 航線 | C4: 起飛 → 抵達 | D4: 機票（2 人） | E4: 行李加購（2 人） | F4: 陸路（日圓，2 人） | G4: 合計（2 人） | H4: 每人 | I4: 說明
A5: 星宇 JX862 | B5: 桃園→仙台 | C5: 11:50 → 16:00 | D5: 34960 | E5: 0 | F5: 3560 | G5: =D5+E5+F5*總覽!$B$5 -> 35707.6 | H5: =G5/2 -> 17853.8 | I5: 含行李；16:00 到仙台，晚上到藏王溫泉
A6: 長榮 BR | B6: 桃園→仙台 | C6: 10:15 → 14:25 | D6: 40532 | E6: 0 | F6: 3560 | G6: =D6+E6+F6*總覽!$B$5 -> 41279.6 | H6: =G6/2 -> 20639.8 | I6: 含行李；最早到仙台
A7: 酷航 TR | B7: 桃園→成田 | C7: 06:50 → 10:55 | D7: 19450 | E7: 2000 | F7: 29540 | G7: =D7+E7+F7*總覽!$B$5 -> 27653.4 | H7: =G7/2 -> 13826.7 | I7: 最便宜；04:50 前要到機場；15:30 左右到山形
A8: 台灣虎航 IT | B8: 桃園→成田 | C8: 06:10 → 10:35 | D8: 21398 | E8: 1900 | F8: 29540 | G8: =D8+E8+F8*總覽!$B$5 -> 29501.4 | H8: =G8/2 -> 14750.7 | I8: 要搭計程車到機場
A9: 日航／華航 | B9: 桃園→成田 | C9: 10:40 → 14:40 | D9: 30484 | E9: 0 | F9: 29540 | G9: =D9+E9+F9*總覽!$B$5 -> 36687.4 | H9: =G9/2 -> 18343.7 | I9: 含行李；時間合理
A10: 星宇 | B10: 桃園→成田 | C10: 10:10 → 14:20 | D10: 33960 | E10: 0 | F10: 29540 | G10: =D10+E10+F10*總覽!$B$5 -> 40163.4 | H10: =G10/2 -> 20081.7 | I10: 含行李
A11: 華航／日航 | B11: 松山→羽田 | C11: 09:00 → 12:50 | D11: 34504 | E11: 0 | F11: 24600 | G11: =D11+E11+F11*總覽!$B$5 -> 39670 | H11: =G11/2 -> 19835 | I11: 含行李；從淡水搭捷運就到
A12: 長榮 | B12: 松山→羽田 | C12: 07:15 → 11:00 | D12: 34630 | E12: 0 | F12: 24600 | G12: =D12+E12+F12*總覽!$B$5 -> 39796 | H12: =G12/2 -> 19898 | I12: 含行李；最早到、離家最近
A13: 陸路：仙台＝機場線 ¥680＋仙台→山形巴士 ¥1,100；成田＝成田特快約 ¥3,100＋新幹線東京→山形 ¥11,670；羽田＝約 ¥630＋¥11,670（每人）。
A15: 回程 2/1（一） | B15: 航線 | C15: 起飛 → 抵達 | D15: 機票（2 人） | E15: 行李加購（2 人） | G15: 合計（2 人） | H15: 每人 | I15: 說明
A16: 長榮 直飛 | B16: 青森→桃園 | C16: 15:30 → 19:00 | D16: 30174 | E16: 0 | G16: =D16+E16 -> 30174 | H16: =G16/2 -> 15087 | I16: 含行李；要把 1/30–1/31 行程改往北走
A17: 韓亞／大韓 經首爾 | B17: 仙台→桃園 | C17: 12:45 → 18:10 | D17: 35947 | E17: 0 | G17: =D17+E17 -> 35947 | H17: =G17/2 -> 17973.5 | I17: 仁川轉機 1 小時；從仙台回、不換機場
A18: 台灣虎航 直飛 | B18: 仙台→高雄 | C18: 18:50 → 22:30 | D18: 36317 | E18: 1900 | G18: =D18+E18 -> 38217 | H18: =G18/2 -> 19108.5 | I18: 落地高雄，當晚可能要住高雄
A19: 台灣虎航 直飛 | B19: 新潟→桃園 | C19: 19:00 → 22:30 | D19: 21923 | E19: 1900 | G19: =D19+E19 -> 23823 | H19: =G19/2 -> 11911.5 | I19: 最便宜，但離銀山溫泉遠、落地晚
A20: 日航轉長榮 經札幌 | B20: 仙台→桃園 | C20: 12:15 → 18:55 | D20: 53877 | E20: 0 | G20: =D20+E20 -> 53877 | H20: =G20/2 -> 26938.5 | I20: 新千歲轉機 1 小時 50 分
A21: 星宇 直飛（商務艙） | B21: 仙台→桃園 | C21: 17:25 → 20:35 | D21: 69051 | E21: 0 | G21: =D21+E21 -> 69051 | H21: =G21/2 -> 34525.5 | I21: 經濟艙已售完
A22: 泰國獅航（參考：東京回） | B22: 成田→桃園 | C22: 18:15 → 21:10 | D22: 20764 | E22: 2000 | G22: =D22+E22 -> 22764 | H22: =G22/2 -> 11382 | I22: 若改成東京進出才適用
A23: 酷航（參考：東京回） | B23: 成田→桃園 | C23: 19:45 → 22:55 | D23: 21680 | E23: 2000 | G23: =D23+E23 -> 23680 | H23: =G23/2 -> 11840 | I23: 若改成東京進出才適用

Sheet 每日行程
A1: 定案行程：早去晚回 6 天 5 夜（2027/1/26 二 – 1/31 日，請假 4 天）
A2: 去程長榮 BR118 08:45→13:00、回程虎航 IT255 19:00→21:55。時間為當地時間（日本比台灣快 1 小時），車班時間為估計，出發前請用 Google Maps 或 Jorudan 查當天班次。
A4: 日期 | B4: 時間 | C4: 行程 | D4: 交通 | E4: 備註
A5: 1/26 二 | B5: 05:40 | C5: 從淡水出發 | D5: 淡水信義線 → 台北車站轉機場捷運直達車 | E5: 搭 05:30 前後的首班車；6:45 前到桃園機場第 2 航廈（長榮）
B6: 08:45 | C6: 長榮 BR118 桃園 → 仙台 | D6: 飛行約 3 小時 15 分 | E6: 含 23kg 托運行李與機上餐
B7: 13:00 | C7: 抵達仙台機場 | E7: 入境約 30–45 分鐘
B8: 13:50 | C8: 仙台機場 → 仙台站 | D8: 仙台機場線約 25 分鐘，¥680 | E8: 可以用 Suica
B9: 14:30 | C9: 飯店寄放行李 | E9: 住仙台站附近，1/30 回來時可以住同一間
B10: 15:00 | C10: 仙台城跡（伊達政宗騎馬像）、瑞鳳殿 | D10: 觀光巴士 Loople 一日券 ¥630 | E10: 城跡可以俯瞰仙台市景；冬天 16:50 左右日落，拍夕景剛好
B11: 18:00 | C11: 晚餐：牛舌定食 | E11: 推薦利久、善治郎，一番町一帶
A12: 1/27 三 | B12: 08:30 | C12: 仙台 → 山寺 | D12: JR 仙山線約 1 小時 | E12: 行李可以寄放在山寺站前的置物櫃或店家（數量有限，也可以先用宅配寄到藏王的旅館）
B13: 09:40 | C13: 山寺（立石寺）登 1,015 階石梯 | E13: 雪景很美，但階梯容易滑，請穿防滑鞋或帶冰爪；來回約 1.5–2 小時
B14: 12:00 | C14: 午餐：力蒟蒻、山形蕎麥麵
B15: 13:30 | C15: 山寺 → 山形站 | D15: JR 仙山線約 20 分鐘
B16: 14:30 | C16: 山形站 → 藏王溫泉 | D16: 山交巴士約 40 分鐘，¥1,200 | E16: 也可以買樹冰觀景套票 ¥6,600（巴士來回＋纜車）
B17: 15:30 | C17: 入住藏王溫泉旅館、泡硫磺泉 | E17: 共同浴場上湯、下湯、川原湯每次約 ¥200
B18: 18:00 | C18: 樹冰夜間點燈（幻想迴廊） | D18: 藏王纜車 | E18: 點燈只在特定日期的傍晚，要先確認 1/27 有沒有開，有些需要預約
A19: 1/28 四 | B19: 08:30 | C19: 藏王纜車上山頂看樹冰（白天） | D19: 藏王纜車來回 ¥4,400 | E19: 早上風比較小，比較不會停駛；山頂可能低於 −10°C
B20: 12:00 | C20: 午餐、溫泉街散步
B21: 14:00 | C21: 藏王溫泉 → 山形站 | D21: 山交巴士約 40 分鐘，¥1,200
B22: 15:00 | C22: 山形市區：霞城公園、文翔館 | D22: 步行或計程車 | E22: 文翔館免費入館
B23: 18:00 | C23: 晚餐：米澤牛或山形芋煮 | E23: 住山形站附近
A24: 1/29 五 | B24: 10:00 | C24: 山形睡飽、早午餐 | E24: 也可以順路去天童看將棋駒
B25: 12:30 | C25: 山形 → 大石田 | D25: JR 奧羽本線普通車約 1 小時，或新幹線翼號約 35 分鐘
B26: 14:00 | C26: 大石田站 → 銀山溫泉 | D26: はながさ巴士約 35 分鐘，¥1,000（只收現金） | E26: 先問旅館有沒有大石田站接送
B27: 15:00 | C27: ♨ 入住銀山溫泉（已訂） | E27: 住宿旅客不受冬季日歸管制
B28: 16:45 | C28: 藍調時刻＋瓦斯燈點燈，拍照黃金時段 | E28: 白銀橋、溫泉街中段是經典機位；建議帶腳架
B29: 18:30 | C29: 旅館晚餐、泡湯
B30: 21:00 | C30: 夜間溫泉街散步、雪景拍照 | E30: 一日遊客都離開了，人最少
A31: 1/30 六 | B31: 06:30 | C31: 清晨溫泉街拍照 | E31: 沒有人潮，很適合拍乾淨的雪景
B32: 08:00 | C32: 旅館早餐、白銀瀑布散步
B33: 10:30 | C33: 退房 → 大石田站 | D33: はながさ巴士約 35 分鐘，¥1,000
B34: 11:30 | C34: 大石田 → 仙台 | D34: JR 奧羽本線到羽前千歲轉仙山線，約 2–2.5 小時，¥1,690 | E34: 大雪時容易誤點，請預留時間
B35: 14:30 | C35: 回到仙台飯店寄放行李
B36: 15:00 | C36: 逛一番町、定禪寺通，買伴手禮 | E36: 萩之月、毛豆泥麻糬（ずんだ餅）
B37: 18:30 | C37: 晚餐：仙台海鮮或燒肉 | E37: 住仙台站附近
A38: 1/31 日 | B38: 08:00 | C38: 退房，大件行李寄放在飯店或仙台站置物櫃
B39: 08:30 | C39: 仙台 → 松島海岸 | D39: JR 仙石線約 40 分鐘
B40: 09:30 | C40: 松島遊覽船（約 50 分鐘） | D40: 約 ¥1,500
B41: 11:00 | C41: 瑞巖寺、五大堂 | D41: 瑞巖寺 ¥700
...

Sheet 機票價格
A1: 所有航班與票價（每人，新台幣）
A2: 藍字＝網路參考價；黃底 J、K 欄請填你在官網查到的實際價格（留空則沿用參考價）。時間為當地時間。
A4: 編號 | B4: 航線 | C4: 航空 | D4: 航班號（去/回） | E4: 去程時間 | F4: 回程時間 | G4: 飛行日 | H4: 參考單程價 | I4: 參考來回價 | J4: 實際單程價（請填） | K4: 實際來回價（請填） | L4: 採用單程價 | M4: 採用來回價 | N4: 含托運行李 | O4: 行李加購／每段 | P4: 資料來源與備註
A5: F1 | B5: 桃園⇄仙台 | C5: 台灣虎航 | D5: IT254 / IT255 | E5: 13:45→18:10 | F5: 19:00→21:55 | G5: 過去為二、四、日（待確認） | H5: 4743 | I5: 9676 | L5: =IF(J5>0,J5,H5) -> 4743 | M5: =IF(K5>0,K5,I5) -> 9676 | N5: 否 | O5: 950 | P5: 單程：HotelsCombined／Kayak 2026 最低價；來回：Google Flights 最低價；促銷曾見 7,206。行李 20kg 訂票時加購 NT$950（虎航官網費用表）
A6: F2 | B6: 桃園⇄仙台 | C6: 長榮航空 | D6: BR118 / BR117 | E6: 08:45→13:00 | F6: 14:30→17:45 | G6: 二、三、四、六（待確認） | H6: 9845 | I6: 17878 | L6: =IF(J6>0,J6,H6) -> 9845 | M6: =IF(K6>0,K6,I6) -> 17878 | N6: 是 23kg | O6: 0 | P6: 來回：長榮官網 2027/1 起價 TWD 17,878；單程：比價網最低價
A7: F3 | B7: 桃園⇄仙台 | C7: 星宇航空 | D7: JX862 / JX863 | E7: 11:40→16:00 | F7: 17:20→20:10 | G7: 每日 | H7: 9720 | I7: 19586 | L7: =IF(J7>0,J7,H7) -> 9720 | M7: =IF(K7>0,K7,I7) -> 19586 | N7: 是 23kg | O7: 0 | P7: 來回：星宇官網 2027/1 起價 TWD 19,586；單程：比價網最低價
A8: F4 | B8: 松山⇄羽田 | C8: 長榮航空 | D8: BR192、BR190 / BR189、BR191 | E8: 07:15→11:05；16:25→20:15 | F8: 班次多（待確認） | G8: 每日 | H8: 10361 | I8: 16526 | L8: =IF(J8>0,J8,H8) -> 10361 | M8: =IF(K8>0,K8,I8) -> 16526 | N8: 是 23kg | O8: 0 | P8: 航線最低價（未分航空）：來回 Trip.com NT$16,526 起；單程 Expedia NT$10,361 起。班表為 2023 年資料
A9: F5 | B9: 松山⇄羽田 | C9: 中華航空 | D9: CI220、CI222 / CI221、CI223 | E9: 08:50→12:45；18:25→22:15 | F9: 班次多（待確認） | G9: 每日 | H9: 10361 | I9: 16526 | L9: =IF(J9>0,J9,H9) -> 10361 | M9: =IF(K9>0,K9,I9) -> 16526 | N9: 是 23kg | O9: 0 | P9: 同 F4，航線最低價參考
A10: F6 | B10: 松山⇄羽田 | C10: 日本航空 | D10: JL096、JL098 / JL097、JL099 | E10: 09:30→13:20；15:35 起飛 | F10: 班次多（待確認） | G10: 每日 | H10: 10361 | I10: 16526 | L10: =IF(J10>0,J10,H10) -> 10361 | M10: =IF(K10>0,K10,I10) -> 16526 | N10: 是 23kg | O10: 0 | P10: 同 F4，航線最低價參考
A11: F7 | B11: 松山⇄羽田 | C11: 全日空 | D11: NH852、NH854 / NH853、NH855 | E11: 13:30→17:30；16:50 起飛 | F11: 班次多（待確認） | G11: 每日 | H11: 10361 | I11: 16526 | L11: =IF(J11>0,J11,H11) -> 10361 | M11: =IF(K11>0,K11,I11) -> 16526 | N11: 是 23kg | O11: 0 | P11: 同 F4，航線最低價參考
A12: F8 | B12: 桃園⇄羽田 | C12: 樂桃航空 | D12: MM | E12: 依官網 | F12: 依官網 | G12: 每日 | H12: 5386 | I12: =H12*2 -> 10772 | L12: =IF(J12>0,J12,H12) -> 5386 | M12: =IF(K12>0,K12,I12) -> 10772 | N12: 否 | O12: 1000 | P12: 單程：比價網近期最低 NT$5,386（促銷曾見 2,890 起）；來回＝單程×2 估算；行李費為估計值
A13: F9 | B13: 桃園⇄成田 | C13: 捷星日本 | D13: GK | E13: 依官網 | F13: 依官網 | G13: 每日 | H13: 3748 | I13: =H13*2 -> 7496 | L13: =IF(J13>0,J13,H13) -> 3748 | M13: =IF(K13>0,K13,I13) -> 7496 | N13: 否 | O13: 1000 | P13: 單程：比價網近期最低 NT$3,748；來回＝單程×2 估算；行李費為估計值
A14: F10 | B14: 桃園⇄羽田 | C14: 台灣虎航 | D14: IT | E14: 依官網 | F14: 依官網 | G14: 每日 | H14: 6702 | I14: =H14*2 -> 13404 | L14: =IF(J14>0,J14,H14) -> 6702 | M14: =IF(K14>0,K14,I14) -> 13404 | N14: 否 | O14: 950 | P14: 單程：比價網近期最低 NT$6,702；來回＝單程×2 估算
A16: 飛東京時的陸路交通參考：山形新幹線 東京⇄大石田 指定席單程 ¥12,580（駅探）；羽田⇄東京站 約 ¥500（估計）。

Sheet 方案比較
A1: 機票組合比較（每人，新台幣）
A2: 機票與行李由「機票價格」工作表自動帶入（綠字）；H 欄是相對於仙台進出多出來的陸路交通（日圓，藍字＝估計值，可改）。
A4: 代號 | B4: 方案 | C4: 日期 | D4: 請假天數 | E4: 去程 | F4: 回程 | G4: 機票 | H4: 行李加購 | I4: 額外陸路（日圓） | J4: 額外陸路（新台幣） | K4: 機票＋額外交通 | L4: 單程到銀山 | M4: 說明
A5: ★ | B5: 早去晚回：長榮去＋虎航回（定案） | C5: 1/26 二–1/31 日 | D5: 4 | E5: BR118 08:45 桃園→仙台 13:00 | F5: IT255 19:00 仙台→桃園 21:55 | G5: =機票價格!L6+機票價格!L5 -> 14588 | H5: =機票價格!O5 -> 950 | I5: 0 | J5: =I5*總覽!$B$5 -> 0 | K5: =G5+H5+J5 -> 15538 | L5: 2–3 小時 | M5: 去程中午就到仙台、回程晚上才起飛，頭尾兩天都能玩。需確認 1/26（二）長榮、1/31（日）虎航有飛；備案：去程星宇 JX862 11:40、回程星宇 JX863 17:20（每日）
A6: A | B6: 虎航來回（最便宜） | C6: 1/26 二–1/31 日 | D6: 4 | E6: IT254 桃園→仙台 | F6: IT255 仙台→桃園 | G6: =機票價格!M5 -> 9676 | H6: =2*機票價格!O5 -> 1900 | I6: 0 | J6: =I6*總覽!$B$5 -> 0 | K6: =G6+H6+J6 -> 11576 | L6: 2–3 小時 | M6: 最便宜；回程 19:00 起飛，最後一天可玩松島。需確認 1 月二、日有飛
A7: B | B7: 長榮去＋虎航回 | C7: 1/27 三–1/31 日 | D7: 3 | E7: BR118 桃園→仙台 | F7: IT255 仙台→桃園 | G7: =機票價格!L6+機票價格!L5 -> 14588 | H7: =機票價格!O5 -> 950 | I7: 0 | J7: =I7*總覽!$B$5 -> 0 | K7: =G7+H7+J7 -> 15538 | L7: 2–3 小時 | M7: 只請 3 天；兩段分開買單程
A8: C | B8: 星宇來回 | C8: 1/27 三–1/31 日 | D8: 3 | E8: JX862 桃園→仙台 | F8: JX863 仙台→桃園 | G8: =機票價格!M7 -> 19586 | H8: =2*機票價格!O7 -> 0 | I8: 0 | J8: =I8*總覽!$B$5 -> 0 | K8: =G8+H8+J8 -> 19586 | L8: 2–3 小時 | M8: 每天都飛，日期最彈性；含行李和餐點
A9: D | B9: 松山⇄羽田來回（長榮） | C9: 1/26 二–1/31 日 | D9: 4 | E9: BR192 松山→羽田 | F9: BR189/191 羽田→松山 | G9: =機票價格!M8 -> 16526 | H9: =2*機票價格!O8 -> 0 | I9: =2*(12580+500)-1690-680*2 -> 23110 | J9: =I9*總覽!$B$5 -> 4853.1 | K9: =G9+H9+J9 -> 21379.1 | L9: 4.5–5 小時 | M9: 離家最近；可順遊東京。額外交通＝新幹線來回＋羽田⇄東京，扣掉仙台方案的 JR 與機場線
A10: E | B10: 開口：虎航去仙台＋羽田回松山 | C10: 1/26 二–1/31 日 | D10: 4 | E10: IT254 桃園→仙台 | F10: BR189/191 羽田→松山 | G10: =機票價格!L5+機票價格!L8 -> 15104 | H10: =機票價格!O5 -> 950 | I10: =12580+500-1690-680 -> 10710 | J10: =I10*總覽!$B$5 -> 2249.1 | K10: =G10+H10+J10 -> 18303.1 | L10: 2–3 小時 | M10: 去程最便宜；1/30 從大石田搭新幹線直達東京，不走回頭路
A11: F | B11: 樂桃 桃園⇄羽田＋新幹線 | C11: 1/26 二–1/31 日 | D11: 4 | E11: 樂桃 桃園→羽田 | F11: 樂桃 羽田→桃園 | G11: =機票價格!M12 -> 10772 | H11: =2*機票價格!O12 -> 2000 | I11: =2*(12580+500)-1690-680*2 -> 23110 | J11: =I11*總覽!$B$5 -> 4853.1 | K11: =G11+H11+J11 -> 17625.1 | L11: 4.5–5 小時 | M11: 只有在東京機票特價很多時才划算
A13: 最便宜方案： | C13: =INDEX(B5:B11,MATCH(MIN(K5:K11),K5:K11,0)) -> 虎航來回（最便宜） | F13: =MIN(K5:K11) -> 11576

Sheet 行程預算
A1: 定案行程：每日當地花費（每人）
A2: 藍字為估計值，可依實際訂房、車票修改；銀山溫泉住宿引用「總覽」B7。
A4: 日期 | B4: 行程 | C4: 交通方式 | D4: 交通費（日圓） | E4: 住宿地點 | F4: 住宿費（日圓） | G4: 門票／活動（日圓） | H4: 小計（日圓） | I4: 小計（新台幣） | J4: 備註
A5: 1/26 二 | B5: 桃園 → 仙台；下午仙台城跡、瑞鳳殿，晚餐吃牛舌 | C5: 長榮 BR118 08:45→13:00；仙台機場線 ¥680；觀光巴士 Loople 一日券 ¥630 | D5: 1310 | E5: 仙台站周邊 | F5: 9000 | G5: 570 | H5: =D5+F5+G5 -> 10880 | I5: =H5*總覽!$B$5 -> 2284.8 | J5: 瑞鳳殿門票 ¥570；商務旅館估計 ¥8,000–10,000
A6: 1/27 三 | B6: 山寺（立石寺）→ 藏王溫泉，看樹冰夜景 | C6: JR 仙山線 仙台→山寺 → 山形；山交巴士 山形→藏王溫泉 ¥1,200 | D6: 2300 | E6: 藏王溫泉 | F6: 20000 | G6: 0 | H6: =D6+F6+G6 -> 22300 | I6: =H6*總覽!$B$5 -> 4683 | J6: 溫泉旅館多含早晚餐，估計 ¥15,000–25,000；JR 車資為估計
A7: 1/28 四 | B7: 藏王樹冰（白天）→ 山形市區 | C7: 藏王纜車來回 ¥4,400；巴士 藏王→山形 ¥1,200 | D7: 1200 | E7: 山形站周邊 | F7: 8000 | G7: 4400 | H7: =D7+F7+G7 -> 13600 | I7: =H7*總覽!$B$5 -> 2856 | J7: 可改買樹冰觀景套票 ¥6,600（含巴士來回＋纜車）
A8: 1/29 五 | B8: 銀山溫泉 ♨（已訂） | C8: JR 山形→大石田；巴士 大石田→銀山溫泉 ¥1,000（只收現金） | D8: 1900 | E8: 銀山溫泉 | F8: =總覽!B7 -> 0 | G8: 0 | H8: =D8+F8+G8 -> 1900 | I8: =H8*總覽!$B$5 -> 399 | J8: JR 車資為估計；請向旅館確認是否有接送
A9: 1/30 六 | B9: 銀山溫泉清晨拍照 → 仙台 | C9: 巴士 銀山溫泉→大石田 ¥1,000；JR 大石田→仙台 ¥1,690 | D9: 2690 | E9: 仙台站周邊 | F9: 9000 | G9: 0 | H9: =D9+F9+G9 -> 11690 | I9: =H9*總覽!$B$5 -> 2454.9
A10: 1/31 日 | B10: 松島（遊覽船、瑞巖寺、烤牡蠣）→ 仙台機場 → 桃園 | C10: JR 仙石線 來回約 ¥860；仙台機場線 ¥680 | D10: 1540 | E10: — | F10: 0 | G10: 2200 | H10: =D10+F10+G10 -> 3740 | I10: =H10*總覽!$B$5 -> 785.4 | J10: 遊覽船約 ¥1,500＋瑞巖寺 ¥700；虎航 IT255 19:00→21:55
A11: 合計 | D11: =SUM(D5:D10) -> 10940 | F11: =SUM(F5:F10) -> 46000 | G11: =SUM(G5:G10) -> 7170 | H11: =SUM(H5:H10) -> 64110 | I11: =SUM(I5:I10) -> 13463.1
A12: 餐費（每日） | H12: 5000 | J12: 估計：旅館含餐的日子實際會更少
A13: 餐費合計（6 天） | H13: =H12*6 -> 30000 | I13: =H13*總覽!$B$5 -> 6300
A14: 當地花費總計 | I14: =I11+I13 -> 19763.1

Sheet 待辦清單
A1: 項目 | B1: 建議完成時間 | C1: 狀態 | D1: 備註
A2: 查長榮 1/26（二）BR118 單程、虎航 1/31（日）IT255 單程價格 | B2: 10 月上旬 | C2: 未開始 | D2: 確認這兩天有飛；價格填回「機票價格」J6、J5
A3: 備案：查星宇 JX862／JX863 單程價 | B3: 10 月上旬 | C3: 未開始 | D3: 長榮或虎航當天沒飛時使用，填入 J7
A4: 查松山⇄羽田的價格（開口方案用） | B4: 10 月上旬 | C4: 未開始 | D4: 填入 J8–J11
A5: 訂機票並預購托運行李 | B5: 10 月中 | C5: 未開始 | D5: 虎航訂票時加購 20kg NT$950／段
A6: 訂 1/26 仙台、1/27 藏王溫泉、1/28 山形、1/30 仙台住宿 | B6: 10 月底 | C6: 未開始 | D6: 藏王溫泉旅館冬季容易客滿，建議先訂
A7: 聯絡銀山溫泉旅館，確認接送與冬季入場方式 | B7: 12 月 | C7: 未開始 | D7: 2026–27 冬季管制細則預計年底公布
A8: 準備日圓現金、防滑鞋／冰爪、相機備用電池 | B8: 出發前 1 週 | C8: 未開始 | D8: 大石田巴士只收現金

Sheet 資料來源
A1: 資料 | B1: 網址
A2: 星宇 台北–仙台 2027/1 票價 | B2: https://www.starlux-airlines.com/flights/en/flights-from-taipei-to-sendai
A3: 長榮 台北–仙台 2027/1 票價 | B3: https://flights.evaair.com/en/flights-from-taipei-to-sendai
A4: Google Flights 台北–仙台 | B4: https://www.google.com/travel/flights/flights-from-taipei-city-to-sendai.html
A5: HotelsCombined 桃園–仙台 | B5: https://www.hotelscombined.com.tw/flight-routes/Taipei-City-Taiwan-Taoyuan-Intl-TPE/Sendai-SDJ.ksp
A6: Skyscanner 長榮飛仙台 | B6: https://www.skyscanner.com.tw/flights/airline-flights-to-airport/sdj/eva-air-br/cheap-flights-with-eva-air-br-flights-to-sendai
A7: Trip.com 松山–羽田 | B7: https://www.trip.com/flights/airport-tsa-hnd/
A8: Expedia 松山–羽田 | B8: https://www.expedia.com.tw/en/lp/flights/tsa/hnd/taipei-to-tokyo
A9: 羽田–松山 時刻表 | B9: https://www.haneda-tokyo.com/schedule/hnd-tsa-schedule.html
A10: HotelsCombined 桃園–羽田 | B10: https://www.hotelscombined.com.tw/flight-routes/Taipei-City-Taiwan-Taoyuan-Intl-TPE/Tokyo-Haneda-HND.ksp
A11: Kayak 台北–成田 | B11: https://www.tw.kayak.com/%E8%88%AA%E7%8F%AD/%E5%8F%B0%E5%8C%97-TW1/%E6%9D%B1%E4%BA%AC-%E6%88%90%E7%94%B0%E5%9C%8B%E9%9A%9B%E6%A9%9F%E5%A0%B4-NRT
A12: 虎航 行李費用 | B12: https://www.tigerairtw.com/zh-tw/ready-to-go/fees
... A17: 銀山溫泉交通（仙台–大石田 ¥1,690、巴士 ¥1,000） | B17: https://mimigo.tw/ginzan-onsen/
